<?xml version="1.0" encoding="UTF-8"?>
<!-- Generated by org.testng.reporters.JUnitReportReporter -->
<testsuite hostname="DOLebedev" name="test.exception.ExceptionMessageTest" tests="3" failures="0" timestamp="20 Jul 2015 16:54:39 GMT" time="0.015" errors="1">
  <testcase name="exceptionMsgTestOne" time="0.013" classname="test.exception.ExceptionMessageTest"/>
  <testcase name="exceptionMsgTestThree" time="0.001" classname="test.exception.ExceptionMessageTest">
    <error type="java.io.IOException" message="Fail Message test">
      <![CDATA[java.io.IOException: Fail Message test
	at test.exception.ExceptionMessageTest.exceptionMsgTestThree(ExceptionMessageTest.java:20)
	at sun.reflect.NativeMethodAccessorImpl.invoke0(Native Method)
	at sun.reflect.NativeMethodAccessorImpl.invoke(Unknown Source)
	at sun.reflect.DelegatingMethodAccessorImpl.invoke(Unknown Source)
	at java.lang.reflect.Method.invoke(Unknown Source)
	at org.testng.internal.MethodInvocationHelper.invokeMethod(MethodInvocationHelper.java:85)
	at org.testng.internal.Invoker.invokeMethod(Invoker.java:648)
	at org.testng.internal.Invoker.invokeTestMethod(Invoker.java:834)
	at org.testng.internal.Invoker.invokeTestMethods(Invoker.java:1142)
	at org.testng.internal.TestMethodWorker.invokeTestMethods(TestMethodWorker.java:124)
	at org.testng.internal.TestMethodWorker.run(TestMethodWorker.java:108)
	at org.testng.TestRunner.privateRun(TestRunner.java:771)
	at org.testng.TestRunner.run(TestRunner.java:621)
	at org.testng.SuiteRunner.runTest(SuiteRunner.java:357)
	at org.testng.SuiteRunner.runSequentially(SuiteRunner.java:352)
	at org.testng.SuiteRunner.privateRun(SuiteRunner.java:310)
	at org.testng.SuiteRunner.run(SuiteRunner.java:259)
	at org.testng.SuiteRunnerWorker.runSuite(SuiteRunnerWorker.java:52)
	at org.testng.SuiteRunnerWorker.run(SuiteRunnerWorker.java:86)
	at org.testng.TestNG.runSuitesSequentially(TestNG.java:1176)
	at org.testng.TestNG.runSuitesLocally(TestNG.java:1101)
	at org.testng.TestNG.run(TestNG.java:1009)
	at org.testng.remote.RemoteTestNG.run(RemoteTestNG.java:111)
	at org.testng.remote.RemoteTestNG.initAndRun(RemoteTestNG.java:204)
	at org.testng.remote.RemoteTestNG.main(RemoteTestNG.java:175)
]]>
    </error>
  </testcase> <!-- exceptionMsgTestThree -->
  <testcase name="exceptionMsgTestTwo" time="0.001" classname="test.exception.ExceptionMessageTest"/>
</testsuite> <!-- test.exception.ExceptionMessageTest -->
