<?xml version="1.0" encoding="UTF-8"?>
<testng-results skipped="0" failed="1" total="3" passed="2">
  <reporter-output>
  </reporter-output>
  <suite name="Default suite" duration-ms="43" started-at="2015-07-20T16:54:39Z" finished-at="2015-07-20T16:54:39Z">
    <groups>
    </groups>
    <test name="Default test" duration-ms="43" started-at="2015-07-20T16:54:39Z" finished-at="2015-07-20T16:54:39Z">
      <class name="test.exception.ExceptionMessageTest">
        <test-method status="PASS" signature="exceptionMsgTestOne()[pri:0, instance:test.exception.ExceptionMessageTest@6f79caec]" name="exceptionMsgTestOne" duration-ms="13" started-at="2015-07-20T19:54:39Z" finished-at="2015-07-20T19:54:39Z">
          <exception class="java.io.IOException">
            <message>
              <![CDATA[Pass Message test]]>
            </message>
            <full-stacktrace>
              <![CDATA[java.io.IOException: Pass Message test
	at test.exception.ExceptionMessageTest.exceptionMsgTestOne(ExceptionMessageTest.java:10)
	at sun.reflect.NativeMethodAccessorImpl.invoke0(Native Method)
	at sun.reflect.NativeMethodAccessorImpl.invoke(Unknown Source)
	at sun.reflect.DelegatingMethodAccessorImpl.invoke(Unknown Source)
	at java.lang.reflect.Method.invoke(Unknown Source)
	at org.testng.internal.MethodInvocationHelper.invokeMethod(MethodInvocationHelper.java:85)
	at org.testng.internal.Invoker.invokeMethod(Invoker.java:648)
	at org.testng.internal.Invoker.invokeTestMethod(Invoker.java:834)
	at org.testng.internal.Invoker.invokeTestMethods(Invoker.java:1142)
	at org.testng.internal.TestMethodWorker.invokeTestMethods(TestMethodWorker.java:124)
	at org.testng.internal.TestMethodWorker.run(TestMethodWorker.java:108)
	at org.testng.TestRunner.privateRun(TestRunner.java:771)
	at org.testng.TestRunner.run(TestRunner.java:621)
	at org.testng.SuiteRunner.runTest(SuiteRunner.java:357)
	at org.testng.SuiteRunner.runSequentially(SuiteRunner.java:352)
	at org.testng.SuiteRunner.privateRun(SuiteRunner.java:310)
	at org.testng.SuiteRunner.run(SuiteRunner.java:259)
	at org.testng.SuiteRunnerWorker.runSuite(SuiteRunnerWorker.java:52)
	at org.testng.SuiteRunnerWorker.run(SuiteRunnerWorker.java:86)
	at org.testng.TestNG.runSuitesSequentially(TestNG.java:1176)
	at org.testng.TestNG.runSuitesLocally(TestNG.java:1101)
	at org.testng.TestNG.run(TestNG.java:1009)
	at org.testng.remote.RemoteTestNG.run(RemoteTestNG.java:111)
	at org.testng.remote.RemoteTestNG.initAndRun(RemoteTestNG.java:204)
	at org.testng.remote.RemoteTestNG.main(RemoteTestNG.java:175)
]]>
            </full-stacktrace>
          </exception> <!-- java.io.IOException -->
          <reporter-output>
          </reporter-output>
        </test-method> <!-- exceptionMsgTestOne -->
        <test-method status="FAIL" signature="exceptionMsgTestThree()[pri:0, instance:test.exception.ExceptionMessageTest@6f79caec]" name="exceptionMsgTestThree" duration-ms="1" started-at="2015-07-20T19:54:39Z" finished-at="2015-07-20T19:54:39Z">
          <exception class="java.io.IOException">
            <message>
              <![CDATA[Fail Message test]]>
            </message>
            <full-stacktrace>
              <![CDATA[java.io.IOException: Fail Message test
	at test.exception.ExceptionMessageTest.exceptionMsgTestThree(ExceptionMessageTest.java:20)
	at sun.reflect.NativeMethodAccessorImpl.invoke0(Native Method)
	at sun.reflect.NativeMethodAccessorImpl.invoke(Unknown Source)
	at sun.reflect.DelegatingMethodAccessorImpl.invoke(Unknown Source)
	at java.lang.reflect.Method.invoke(Unknown Source)
	at org.testng.internal.MethodInvocationHelper.invokeMethod(MethodInvocationHelper.java:85)
	at org.testng.internal.Invoker.invokeMethod(Invoker.java:648)
	at org.testng.internal.Invoker.invokeTestMethod(Invoker.java:834)
	at org.testng.internal.Invoker.invokeTestMethods(Invoker.java:1142)
	at org.testng.internal.TestMethodWorker.invokeTestMethods(TestMethodWorker.java:124)
	at org.testng.internal.TestMethodWorker.run(TestMethodWorker.java:108)
	at org.testng.TestRunner.privateRun(TestRunner.java:771)
	at org.testng.TestRunner.run(TestRunner.java:621)
	at org.testng.SuiteRunner.runTest(SuiteRunner.java:357)
	at org.testng.SuiteRunner.runSequentially(SuiteRunner.java:352)
	at org.testng.SuiteRunner.privateRun(SuiteRunner.java:310)
	at org.testng.SuiteRunner.run(SuiteRunner.java:259)
	at org.testng.SuiteRunnerWorker.runSuite(SuiteRunnerWorker.java:52)
	at org.testng.SuiteRunnerWorker.run(SuiteRunnerWorker.java:86)
	at org.testng.TestNG.runSuitesSequentially(TestNG.java:1176)
	at org.testng.TestNG.runSuitesLocally(TestNG.java:1101)
	at org.testng.TestNG.run(TestNG.java:1009)
	at org.testng.remote.RemoteTestNG.run(RemoteTestNG.java:111)
	at org.testng.remote.RemoteTestNG.initAndRun(RemoteTestNG.java:204)
	at org.testng.remote.RemoteTestNG.main(RemoteTestNG.java:175)
]]>
            </full-stacktrace>
          </exception> <!-- java.io.IOException -->
          <reporter-output>
          </reporter-output>
        </test-method> <!-- exceptionMsgTestThree -->
        <test-method status="PASS" signature="exceptionMsgTestTwo()[pri:0, instance:test.exception.ExceptionMessageTest@6f79caec]" name="exceptionMsgTestTwo" duration-ms="1" started-at="2015-07-20T19:54:39Z" finished-at="2015-07-20T19:54:39Z">
          <exception class="java.io.IOException">
            <message>
              <![CDATA[Pass Message test]]>
            </message>
            <full-stacktrace>
              <![CDATA[java.io.IOException: Pass Message test
	at test.exception.ExceptionMessageTest.exceptionMsgTestTwo(ExceptionMessageTest.java:15)
	at sun.reflect.NativeMethodAccessorImpl.invoke0(Native Method)
	at sun.reflect.NativeMethodAccessorImpl.invoke(Unknown Source)
	at sun.reflect.DelegatingMethodAccessorImpl.invoke(Unknown Source)
	at java.lang.reflect.Method.invoke(Unknown Source)
	at org.testng.internal.MethodInvocationHelper.invokeMethod(MethodInvocationHelper.java:85)
	at org.testng.internal.Invoker.invokeMethod(Invoker.java:648)
	at org.testng.internal.Invoker.invokeTestMethod(Invoker.java:834)
	at org.testng.internal.Invoker.invokeTestMethods(Invoker.java:1142)
	at org.testng.internal.TestMethodWorker.invokeTestMethods(TestMethodWorker.java:124)
	at org.testng.internal.TestMethodWorker.run(TestMethodWorker.java:108)
	at org.testng.TestRunner.privateRun(TestRunner.java:771)
	at org.testng.TestRunner.run(TestRunner.java:621)
	at org.testng.SuiteRunner.runTest(SuiteRunner.java:357)
	at org.testng.SuiteRunner.runSequentially(SuiteRunner.java:352)
	at org.testng.SuiteRunner.privateRun(SuiteRunner.java:310)
	at org.testng.SuiteRunner.run(SuiteRunner.java:259)
	at org.testng.SuiteRunnerWorker.runSuite(SuiteRunnerWorker.java:52)
	at org.testng.SuiteRunnerWorker.run(SuiteRunnerWorker.java:86)
	at org.testng.TestNG.runSuitesSequentially(TestNG.java:1176)
	at org.testng.TestNG.runSuitesLocally(TestNG.java:1101)
	at org.testng.TestNG.run(TestNG.java:1009)
	at org.testng.remote.RemoteTestNG.run(RemoteTestNG.java:111)
	at org.testng.remote.RemoteTestNG.initAndRun(RemoteTestNG.java:204)
	at org.testng.remote.RemoteTestNG.main(RemoteTestNG.java:175)
]]>
            </full-stacktrace>
          </exception> <!-- java.io.IOException -->
          <reporter-output>
          </reporter-output>
        </test-method> <!-- exceptionMsgTestTwo -->
      </class> <!-- test.exception.ExceptionMessageTest -->
    </test> <!-- Default test -->
  </suite> <!-- Default suite -->
</testng-results>
